<?xml version="1.0" encoding="utf-8"?>
<!-- =================================================================================== -->
<!-- |    This document was autogenerated by xacro from rubot_mecanum.xacro            | -->
<!-- |    EDITING THIS FILE BY HAND IS NOT RECOMMENDED                                 | -->
<!-- =================================================================================== -->
  <!-- ===================== MATERIALS ===================== -->
  <material name="yellow">
    <color rgba="0.8 0.8 0 1"/>
  </material>
  <material name="black">
    <color rgba="0.15 0.15 0.15 1"/>
  </material>
  <material name="light_grey">
    <color rgba="0.75 0.75 0.75 1"/>
  </material>
  <material name="dark_grey">
    <color rgba="0.2 0.2 0.2 1"/>
  </material>
  <material name="red_shiny">
    <color rgba="1 0 0 1"/>
  </material>
  <material name="green">
    <color rgba="0 1 0 1"/>
  </material>

  <!-- ===================== BASE ===================== -->
  <link name="base_footprint"/>

  <joint name="base_link_joint" type="fixed">
    <origin xyz="0 0 0" rpy="0 0 0"/>
    <parent link="base_footprint"/>
    <child link="base_link"/>
  </joint>

  <link name="base_link">
    <visual>
      <geometry>
        <mesh filename="file://$(find my_robot_description)/meshes/rubot/base_link.stl" scale="0.001 0.001 0.001"/>
      </geometry>
      <material name="yellow"/>
    </visual>
    <collision>
      <geometry>
        <box size="0.23 0.12 0.1"/>
      </geometry>
    </collision>
    <inertial>
      <mass value="5"/>
      <inertia ixx="0.0104" ixy="0" ixz="0" iyy="0.0292" iyz="0" izz="0.0375"/>
    </inertial>
  </link>

  <!-- ===================== WHEELS ===================== -->
  <!-- Upper left wheel -->
  <joint name="upper_left_wheel_joint" type="continuous">
    <origin xyz="0.07 0.1 0" rpy="0 0 0"/>
    <parent link="base_link"/>
    <child link="upper_left_wheel"/>
    <axis xyz="0 1 0"/>
  </joint>
  <link name="upper_left_wheel">
    <visual>
      <geometry>
        <mesh filename="file://$(find my_robot_description)/meshes/rubot/upper_left_wheel.stl" scale="0.001 0.001 0.001"/>
      </geometry>
      <material name="light_grey"/>
    </visual>
    <collision>
      <geometry>
        <cylinder radius="0.055" length="0.03"/>
      </geometry>
      <origin rpy="-1.57 0 0" xyz="0 0 0"/>
    </collision>
    <inertial>
      <mass value="0.2"/>
      <inertia ixx="0.000166" iyy="0.000303" izz="0.000166"/>
    </inertial>
  </link>

  <!-- Lower left wheel -->
  <joint name="lower_left_wheel_joint" type="continuous">
    <origin xyz="-0.085 0.1 0" rpy="0 0 0"/>
    <parent link="base_link"/>
    <child link="lower_left_wheel"/>
    <axis xyz="0 1 0"/>
  </joint>
  <link name="lower_left_wheel">
    <visual>
      <geometry>
        <mesh filename="file://$(find my_robot_description)/meshes/rubot/lower_left_wheel.stl" scale="0.001 0.001 0.001"/>
      </geometry>
      <material name="light_grey"/>
    </visual>
    <collision>
      <geometry>
        <cylinder radius="0.055" length="0.03"/>
      </geometry>
      <origin rpy="-1.57 0 0" xyz="0 0 0"/>
    </collision>
    <inertial>
      <mass value="0.2"/>
      <inertia ixx="0.000166" iyy="0.000303" izz="0.000166"/>
    </inertial>
  </link>

  <!-- Upper right wheel -->
  <joint name="upper_right_wheel_joint" type="continuous">
    <origin xyz="0.07 -0.1 0" rpy="0 0 3.14"/>
    <parent link="base_link"/>
    <child link="upper_right_wheel"/>
    <axis xyz="0 -1 0"/>
  </joint>
  <link name="upper_right_wheel">
    <visual>
      <geometry>
        <mesh filename="file://$(find my_robot_description)/meshes/rubot/upper_right_wheel.stl" scale="0.001 0.001 0.001"/>
      </geometry>
      <material name="light_grey"/>
    </visual>
    <collision>
      <geometry>
        <cylinder radius="0.055" length="0.03"/>
      </geometry>
      <origin rpy="-1.57 0 0" xyz="0 0 0"/>
    </collision>
    <inertial>
      <mass value="0.2"/>
      <inertia ixx="0.000166" iyy="0.000303" izz="0.000166"/>
    </inertial>
  </link>

  <!-- Lower right wheel -->
  <joint name="lower_right_wheel_joint" type="continuous">
    <origin xyz="-0.085 -0.1 0" rpy="0 0 3.14"/>
    <parent link="base_link"/>
    <child link="lower_right_wheel"/>
    <axis xyz="0 -1 0"/>
  </joint>
  <link name="lower_right_wheel">
    <visual>
      <geometry>
        <mesh filename="file://$(find my_robot_description)/meshes/rubot/lower_right_wheel.stl" scale="0.001 0.001 0.001"/>
      </geometry>
      <material name="light_grey"/>
    </visual>
    <collision>
      <geometry>
        <cylinder radius="0.055" length="0.03"/>
      </geometry>
      <origin rpy="-1.57 0 0" xyz="0 0 0"/>
    </collision>
    <inertial>
      <mass value="0.2"/>
      <inertia ixx="0.000166" iyy="0.000303" izz="0.000166"/>
    </inertial>
  </link>

  <!-- ===================== CAMERA ===================== -->
  <joint name="joint_camera" type="fixed">
    <origin xyz="0.130 0 0.05" rpy="0 0 0"/>
    <parent link="base_link"/>
    <child link="camera"/>
  </joint>
  <link name="camera">
    <visual>
      <geometry>
        <box size="0.05 0.05 0.025"/>
      </geometry>
      <material name="black"/>
    </visual>
    <collision>
      <geometry>
        <box size="0.05 0.05 0.025"/>
      </geometry>
    </collision>
    <inertial>
      <mass value="0.01"/>
      <inertia ixx="1e-6" iyy="1e-6" izz="1e-6"/>
    </inertial>
  </link>

  <!-- ===================== LIDAR ===================== -->
  <link name="base_scan">
    <visual>
      <geometry>
        <mesh filename="file://$(find my_robot_description)/meshes/rubot/Lidar.stl" scale="0.001 0.001 0.001"/>
      </geometry>
      <material name="black"/>
    </visual>
    <collision>
      <geometry>
        <cylinder radius="0.05" length="0.05"/>
      </geometry>
    </collision>
    <inertial>
      <mass value="0.05"/>
      <inertia ixx="0.001" iyy="0.001" izz="0.001"/>
    </inertial>
  </link>
  <joint name="scan_joint" type="fixed">
    <parent link="base_link"/>
    <child link="base_scan"/>
    <origin xyz="0 0 0.14" rpy="0 0 3.14"/>
    <axis xyz="0 0 1"/>
  </joint>

  <!-- ===================== TOP PART (RED BRILLANT, ARRODONIDA) ===================== -->
  <link name="top_part">
    <visual>
      <geometry>
        <box size="0.10 0.08 0.03"/>
      </geometry>
      <material name="red_shiny"/>
    </visual>
    <collision>
      <geometry>
        <box size="0.10 0.08 0.03"/>
      </geometry>
    </collision>
    <inertial>
      <mass value="0.05"/>
      <inertia ixx="1e-5" iyy="1e-5" izz="1e-5"/>
    </inertial>
  </link>
  <joint name="top_part_joint" type="fixed">
    <parent link="base_link"/>
    <child link="top_part"/>
    <origin xyz="0 0 0.10" rpy="0 0 0"/>
  </joint>

  <!-- ===================== PART BOX ===================== -->
  <link name="part">
    <visual>
      <geometry>
        <mesh filename="file://$(find my_robot_description)/meshes/rubot/number2.stl" scale="0.0008 0.0008 0.0008"/>
      </geometry>
      <material name="light_grey"/>
    </visual>
    <collision>
      <geometry>
        <box size="0.05 0.05 0.025"/>
      </geometry>
    </collision>
    <inertial>
      <mass value="0.01"/>
      <inertia ixx="1e-6" iyy="1e-6" izz="1e-6"/>
    </inertial>
  </link>
  <joint name="joint_part" type="fixed">
    <parent link="base_link"/>
    <child link="part"/>
    <origin xyz="-0.10 0 0.08" rpy="0 0 0"/>
  </joint>

  <!-- ===================== GAZEBO PLUGINS ===================== -->
  <gazebo>
    <plugin name="mecanum_controller" filename="libgazebo_ros_planar_move.so">
      <command_topic>cmd_vel</command_topic>
      <odometry_topic>odom</odometry_topic>
      <odometry_frame>odom</odometry_frame>
      <odometry_rate>20.0</odometry_rate>
      <robot_base_frame>base_footprint</robot_base_frame>
      <publish_odom>true</publish_odom>
      <publish_odom_tf>true</publish_odom_tf>
      <wheel_radius>0.04</wheel_radius>
      <base_length>0.65</base_length>
      <base_width>0.65</base_width>
      <publish_wheel_tf>true</publish_wheel_tf>
      <front_left_joint>upper_left_wheel_joint</front_left_joint>
      <front_right_joint>upper_right_wheel_joint</front_right_joint>
      <rear_left_joint>lower_left_wheel_joint</rear_left_joint>
      <rear_right_joint>lower_right_wheel_joint</rear_right_joint>
      <wheel_max_speed>20.0</wheel_max_speed>
      <wheel_acceleration>10.0</wheel_acceleration>
      <joint_config>1 1 1 1</joint_config>
    </plugin>
  </gazebo>

</robot>
